<?xml version="1.0" ?>
<robot name="robot_assignment" xmlns:xacro="https://www.ros.org/wiki/xacro" >
    
    <xacro:include filename="$(find ExpRoLab_Assignment2)/urdf/materials.xacro" />
    <xacro:include filename="$(find ExpRoLab_Assignment2)/urdf/robot_assignment.gazebo" />


    <!-- Macros for inertia -->
    <xacro:macro name="cylinder_inertia" params="mass r l"> 
        <inertia ixx="${mass*(3*r*r+l*l)/12}" ixy = "0" ixz = "0" 
                 iyy="${mass*(3*r*r+l*l)/12}" iyz = "0" izz="${mass*(r*r)/2}" /> 
    </xacro:macro>

    <xacro:macro name="box_inertia" params="x y z mass">
        <inertia ixx="${mass*(y*y+z*z)/12}" ixy="0.0" ixz="0.0"
                 iyy="${mass*(x*x+z*z)/12}" iyz="0.0" izz="${mass*(x*x+y*y)/12}" />
    </xacro:macro>


    <!-- Macros with relative properties for the geometry -->
    <xacro:property name="wheel_length" value="0.04" />
    <xacro:property name="wheel_radius" value="0.1" />
    <xacro:macro name="wheel_geometry">
        <geometry>
            <cylinder length="${wheel_length}" radius="${wheel_radius}"/>
        </geometry>
    </xacro:macro>

    <xacro:property name="arm_link_length" value="0.15" />
    <xacro:property name="arm_link_radius" value="0.05" />
    <xacro:macro name="arm_link_geometry">
        <geometry>
            <cylinder length="${arm_link_length}" radius="${arm_link_radius}"/>
        </geometry>
    </xacro:macro>


    <!-- Macro for the wheels -->
    <xacro:macro name="link_wheel" params="name">
        <link name="${name}">
            <inertial>
                <mass value="0.2"/>
                <origin rpy="0 1.5707 1.5707" xyz="0 0 0"/>
                <xacro:cylinder_inertia mass="0.2" r="${wheel_radius}" l="${wheel_length}"/>
            </inertial>
            <collision name="${name}_collision">
                <origin rpy="0 1.5707 1.5707" xyz="0 0 0"/>
                <xacro:wheel_geometry />
            </collision>
            <visual name="${name}_visual">
                <origin rpy="0 1.5707 1.5707" xyz="0 0 0"/>
                <xacro:wheel_geometry />
                <material name="blue"/>
            </visual>
        </link>
    </xacro:macro>


    <!-- Macro for the arm links -->
    <xacro:macro name="arm_link" params="name">
        <link name="${name}">
            <inertial>
                <mass value="0.025"/>
                <origin xyz="0 0 0" rpy="0 0 0"/>
                <xacro:cylinder_inertia mass="0.025" r="${arm_link_radius}" l="${arm_link_length}"/>
            </inertial>
            <collision name="${name}_collision">
                <origin rpy="0 0 0" xyz="0 0 0.075"/>
                <xacro:arm_link_geometry />
            </collision>
            <visual name="${name}_visual">
                <origin rpy="0 0 0" xyz="0 0 0.075"/>
                <xacro:arm_link_geometry />
                <material name="red"/>
            </visual>
        </link>
    </xacro:macro>
    

    <!-- Macros for the joints -->
    <xacro:macro name="continuous_joint" params="name child parent origin_xyz axis_xyz">
        <joint name="${name}" type="continuous">
        <origin rpy="0 0 0" xyz="${origin_xyz}"/>
        <child link="${child}"/>
        <parent link="${parent}"/>
        <axis rpy="0 0 0" xyz="${axis_xyz}"/>
        <limit effort="10" velocity="10"/>
        <joint_properties damping="10.0" friction="0.1"/>
        </joint>
    </xacro:macro>

    <xacro:macro name="revolute_joint" params="name child parent origin_xyz axis_xyz">
        <joint name="${name}" type="revolute">
            <origin rpy="0 0 0" xyz="${origin_xyz}"/>
            <child link="${child}"/>
            <parent link="${parent}"/>
            <axis rpy="0 0 0" xyz="${axis_xyz}"/>
            <limit effort="10.0" upper = "1.0" lower = "-1.0" velocity="0.5"/>
            <joint_properties damping="10.0" friction="0.1"/>
        </joint>
    </xacro:macro>

    <xacro:macro name="fixed_joint" params="name child parent origin_xyz">
        <joint name="${name}" type="fixed">
            <origin rpy="0 0 0" xyz="${origin_xyz}"/>
            <child link="${child}"/>
            <parent link="${parent}"/>
        </joint>
    </xacro:macro>


    <!-- Create the chassis of the robot -->
    <link name="link_chassis">
        <pose>0 0 0.1 0 0 0</pose>
        <inertial>
            <mass value="5"/>
            <origin rpy="0 0 0" xyz="0 0 0.1"/>
            <xacro:box_inertia mass="5" x="0.5" y="0.3" z="0.07"/>
        </inertial> 
        <collision name="collision_chassis">
            <geometry>
                <box size="0.5 0.3 0.07"/>
            </geometry>
        </collision> 
        <visual>
            <origin rpy="0 0 0" xyz="0 0 0"/>
            <geometry>
                <box size="0.5 0.3 0.07"/>
            </geometry>
            <material name="orange"/>
        </visual>
        <!-- Caster front -->
        <collision name="caster_front_collision">
            <origin rpy=" 0 0 0" xyz="0.35 0 -0.05"/>
            <geometry>
                <sphere radius="0.05"/>
            </geometry>
            <surface>
                <friction>
                    <ode>
                        <mu>0</mu>
                        <mu2>0</mu2>
                        <slip1>1.0</slip1>
                        <slip2>1.0</slip2>
                    </ode>
                </friction>
            </surface>
        </collision>
        <visual name="caster_front_visual">
            <origin rpy=" 0 0 0" xyz="0.2 0 -0.05"/>
            <geometry>
                <sphere radius="0.05"/>
            </geometry>
        </visual>
    </link>


    <!-- Create the wheels of the robot -->
    <xacro:link_wheel name="link_right_wheel" />
    <xacro:link_wheel name="link_left_wheel" />
    <xacro:continuous_joint name="joint_right_wheel" child="link_right_wheel" parent="link_chassis" origin_xyz="-0.05 -0.15 0" axis_xyz="0 1 0"/>
    <xacro:continuous_joint name="joint_left_wheel" child="link_left_wheel" parent="link_chassis" origin_xyz="-0.05 0.15 0" axis_xyz="0 1 0"/>


    <!-- Create the arm base link and its joint -->
    <link name="arm_base_link">
        <inertial>
            <mass value="0.2"/>
            <origin xyz="0 0 0" rpy="0 0 0" />
            <xacro:box_inertia mass="0.2" x="0.1" y="0.1" z="0.05"/>
        </inertial>
        <collision>
            <origin xyz="0 0 0" rpy="0 0 0"/>
            <geometry>
                <box size="0.1 0.1 0.05"/>
            </geometry>
            </collision>
        <visual>
            <origin xyz="0 0 0" rpy="0 0 0"/>
            <geometry>
                <box size="0.1 0.1 0.05"/>
            </geometry>
            <material name="red"/>
        </visual>
    </link>

    <xacro:fixed_joint name="arm_base_joint" child="arm_base_link" parent="link_chassis" origin_xyz="0 0 0.06" />


    <!-- Create the arm link and their joints -->
    <xacro:arm_link name="arm_link_01"/>
	<xacro:arm_link name="arm_link_02"/>
	<xacro:arm_link name="arm_link_03"/>

    <xacro:continuous_joint name="arm_joint_01" child="arm_link_01" parent="arm_base_link" origin_xyz="0 0 0.025" axis_xyz="0 0 1"/>
	<xacro:revolute_joint name="arm_joint_02" child="arm_link_02" parent="arm_link_01" origin_xyz="0 0 0.15" axis_xyz="0 1 0"/>
	<xacro:revolute_joint name="arm_joint_03" child="arm_link_03" parent="arm_link_02" origin_xyz="0 0 0.15" axis_xyz="0 1 0"/>

    
    <!-- Create the camera -->
    <link name="camera_link">
        <inertial>
            <mass value="1e-5" />
            <origin xyz="0 0 0" rpy="0 0 0"/>
            <xacro:box_inertia mass="1e-5" x="0.1" y="0.1" z="0.1"/>
        </inertial>
        <collision>
            <origin xyz="0 0 0.025" rpy="0 0 0"/>
            <geometry>
                <box size="0.1 0.1 0.1"/>
            </geometry>
        </collision>
        <visual>
            <origin xyz="0 0 0.025" rpy="0 0 0"/>
            <geometry>
                <box size="0.1 0.1 0.1"/>
            </geometry>
        </visual> 
	</link>

    <xacro:fixed_joint name="camera_joint" child="camera_link" parent="arm_link_03" origin_xyz="0 0 0.15" />


    <!-- Create the laser -->
    <link name="laser">
        <inertial>
            <origin xyz="0 0 0" rpy="0 0 0" />
            <mass value="1e-5" />
            <xacro:box_inertia mass="1e-5" x="0.1" y="0.1" z="0.1"/>
        </inertial>
        <visual>
            <origin xyz="0 0 0" rpy="0 0 0" />
            <geometry>
                <box size="0.1 0.1 0.1"/>
            </geometry>
            <material name="blue" />
        </visual>
        <collision>
            <origin xyz="0 0 0" rpy="0 0 0"/>
            <geometry>
                <box size="0.1 0.1 0.1"/>
            </geometry>
        </collision>
    </link>

    <xacro:fixed_joint name="laser_joint" child="laser" parent="link_chassis" origin_xyz="0.25 0 0.05" />


    <!-- Define the transmissions --> 

	<transmission name="arm_joint_01_trans">
		<type>transmission_interface/SimpleTransmission</type>
		<joint name="arm_joint_01">
			<hardwareInterface>hardware_interface/EffortJointInterface</hardwareInterface>
		</joint>
		<actuator name="motor1">
			<hardwareInterface>hardware_interface/EffortJointInterface</hardwareInterface>
			<mechanicalInterface>1</mechanicalInterface>
		</actuator>
	</transmission>

	<transmission name="arm_joint_02_trans">
		<type>transmission_interface/SimpleTransmission</type>
		<joint name="arm_joint_02">
			<hardwareInterface>hardware_interface/EffortJointInterface</hardwareInterface>
		</joint>
		<actuator name="motor2">
			<hardwareInterface>hardware_interface/EffortJointInterface</hardwareInterface>
			<mechanicalInterface>1</mechanicalInterface>
		</actuator>
	</transmission>

	<transmission name="arm_joint_03_trans">
		<type>transmission_interface/SimpleTransmission</type>
		<joint name="arm_joint_03">
			<hardwareInterface>hardware_interface/EffortJointInterface</hardwareInterface>
		</joint>
		<actuator name="motor3">
			<hardwareInterface>hardware_interface/EffortJointInterface</hardwareInterface>
			<mechanicalInterface>1</mechanicalInterface>
		</actuator>
	</transmission>

 </robot>